Workbook

Sheet Lisez-moi
A1: Artaluz — Grille tarifaire à compléter
A3: Remplissez uniquement les cellules jaunes (Prix HT, suppléments HT).
A4: Les prix TTC et les surfaces se calculent automatiquement.
A5: Les formats sont une proposition : ajoutez, supprimez ou modifiez des lignes librement.
A6: Le taux de TVA est réglable dans l'onglet Paramètres (20 % par défaut, hypothèse France).
A8: Exemple de saisie (fictif) :
A9: Bâche 200 × 100 cm → Prix HT : 89,00 → Prix TTC calculé : 106,80

Sheet Produits
A1: Réf | B1: Support | C1: Format | D1: Largeur (cm) | E1: Hauteur (cm) | F1: Surface (m²) | G1: PRHT | H1: Coeff Marge | I1: Prix HT (€) | J1: Prix TTC (€) | K1: Commission artiste | L1: Marge Artaluz | M1: Marge en % | N1: Remarques | O1: Prix TTC final (€) | P1: Prix HT final (€) | Q1: Commission artiste finale (€) | R1: Qté minimum
A2: BAC-01 | B2: Bâche qualité éco | C2: 100 × 50 cm | D2: 100 | E2: 50 | F2: =D2*E2/10000 -> 0.5 | G2: =(F2*1.2*1.76+F2*1.28) -> 1.696 | H2: 15 | I2: =G2*H2 -> 25.44 | J2: =IF(I2="","",I2*(1+Paramètres!$B$2)) -> 30.528 | K2: =I2*0.1 -> 2.544 | L2: =I2-K2-G2 -> 21.2 | M2: =L2/I2 -> 0.83333333 | O2: =IF(J2="","",ROUNDUP(J2+0.01,0)-0.01) -> 30.99 | P2: =IF(O2="","",O2/(1+Paramètres!$B$2)) -> 25.825 | Q2: =IF(P2="","",P2*0.1) -> 2.5825 | R2: 1
A3: BAC-02 | B3: Bâche qualité éco | C3: 150 × 50 cm | D3: 150 | E3: 50 | F3: =D3*E3/10000 -> 0.75 | G3: =(F3*1.2*1.76+F3*1.28) -> 2.544 | H3: =H2 -> 15 | I3: =G3*H3 -> 38.16 | J3: =IF(I3="","",I3*(1+Paramètres!$B$2)) -> 45.792 | K3: =I3*0.1 -> 3.816 | L3: =I3-K3-G3 -> 31.8 | M3: =L3/I3 -> 0.83333333 | O3: =IF(J3="","",ROUNDUP(J3+0.01,0)-0.01) -> 45.99 | P3: =IF(O3="","",O3/(1+Paramètres!$B$2)) -> 38.325 | Q3: =IF(P3="","",P3*0.1) -> 3.8325 | R3: 1
A4: BAC-03 | B4: Bâche qualité éco | C4: 200 × 50 cm | D4: 200 | E4: 50 | F4: =D4*E4/10000 -> 1 | G4: =(F4*1.2*1.76+F4*1.28) -> 3.392 | H4: =H3 -> 15 | I4: =G4*H4 -> 50.88 | J4: =IF(I4="","",I4*(1+Paramètres!$B$2)) -> 61.056 | K4: =I4*0.1 -> 5.088 | L4: =I4-K4-G4 -> 42.4 | M4: =L4/I4 -> 0.83333333 | O4: =IF(J4="","",ROUNDUP(J4+0.01,0)-0.01) -> 61.99 | P4: =IF(O4="","",O4/(1+Paramètres!$B$2)) -> 51.658333 | Q4: =IF(P4="","",P4*0.1) -> 5.1658333 | R4: 1
A5: BAC-04 | B5: Bâche qualité éco | C5: 100 × 100 cm | D5: 100 | E5: 100 | F5: =D5*E5/10000 -> 1 | G5: =(F5*1.2*1.76+F5*1.28) -> 3.392 | H5: =H4 -> 15 | I5: =G5*H5 -> 50.88 | J5: =IF(I5="","",I5*(1+Paramètres!$B$2)) -> 61.056 | K5: =I5*0.1 -> 5.088 | L5: =I5-K5-G5 -> 42.4 | M5: =L5/I5 -> 0.83333333 | O5: =IF(J5="","",ROUNDUP(J5+0.01,0)-0.01) -> 61.99 | P5: =IF(O5="","",O5/(1+Paramètres!$B$2)) -> 51.658333 | Q5: =IF(P5="","",P5*0.1) -> 5.1658333 | R5: 1
A6: BAC-05 | B6: Bâche qualité éco | C6: 150 × 100 cm | D6: 150 | E6: 100 | F6: =D6*E6/10000 -> 1.5 | G6: =(F6*1.2*1.76+F6*1.28) -> 5.088 | H6: =H5 -> 15 | I6: =G6*H6 -> 76.32 | J6: =IF(I6="","",I6*(1+Paramètres!$B$2)) -> 91.584 | K6: =I6*0.1 -> 7.632 | L6: =I6-K6-G6 -> 63.6 | M6: =L6/I6 -> 0.83333333 | O6: =IF(J6="","",ROUNDUP(J6+0.01,0)-0.01) -> 91.99 | P6: =IF(O6="","",O6/(1+Paramètres!$B$2)) -> 76.658333 | Q6: =IF(P6="","",P6*0.1) -> 7.6658333 | R6: 1
A7: BAC-06 | B7: Bâche qualité éco | C7: 200 × 100 cm | D7: 200 | E7: 100 | F7: =D7*E7/10000 -> 2 | G7: =(F7*1.2*1.76+F7*1.28) -> 6.784 | H7: =H6 -> 15 | I7: =G7*H7 -> 101.76 | J7: =IF(I7="","",I7*(1+Paramètres!$B$2)) -> 122.112 | K7: =I7*0.1 -> 10.176 | L7: =I7-K7-G7 -> 84.8 | M7: =L7/I7 -> 0.83333333 | O7: =IF(J7="","",ROUNDUP(J7+0.01,0)-0.01) -> 122.99 | P7: =IF(O7="","",O7/(1+Paramètres!$B$2)) -> 102.49167 | Q7: =IF(P7="","",P7*0.1) -> 10.249167 | R7: 1
A8: BAC-07 | B8: Bâche qualité éco | C8: 250 × 100 cm | D8: 250 | E8: 100 | F8: =D8*E8/10000 -> 2.5 | G8: =(F8*1.2*1.76+F8*1.28) -> 8.48 | H8: =H7 -> 15 | I8: =G8*H8 -> 127.2 | J8: =IF(I8="","",I8*(1+Paramètres!$B$2)) -> 152.64 | K8: =I8*0.1 -> 12.72 | L8: =I8-K8-G8 -> 106 | M8: =L8/I8 -> 0.83333333 | O8: =IF(J8="","",ROUNDUP(J8+0.01,0)-0.01) -> 152.99 | P8: =IF(O8="","",O8/(1+Paramètres!$B$2)) -> 127.49167 | Q8: =IF(P8="","",P8*0.1) -> 12.749167 | R8: 1
A9: BAC-08 | B9: Bâche qualité éco | C9: 300 × 100 cm | D9: 300 | E9: 100 | F9: =D9*E9/10000 -> 3 | G9: =(F9*1.2*1.76+F9*1.28) -> 10.176 | H9: =H8 -> 15 | I9: =G9*H9 -> 152.64 | J9: =IF(I9="","",I9*(1+Paramètres!$B$2)) -> 183.168 | K9: =I9*0.1 -> 15.264 | L9: =I9-K9-G9 -> 127.2 | M9: =L9/I9 -> 0.83333333 | O9: =IF(J9="","",ROUNDUP(J9+0.01,0)-0.01) -> 183.99 | P9: =IF(O9="","",O9/(1+Paramètres!$B$2)) -> 153.325 | Q9: =IF(P9="","",P9*0.1) -> 15.3325 | R9: 1
A10: BAC-09 | B10: Bâche qualité éco | C10: 100 × 130 cm | D10: 100 | E10: 130 | F10: =D10*E10/10000 -> 1.3 | G10: =(F10*1.2*1.76+F10*1.28) -> 4.4096 | H10: =H9 -> 15 | I10: =G10*H10 -> 66.144 | J10: =IF(I10="","",I10*(1+Paramètres!$B$2)) -> 79.3728 | K10: =I10*0.1 -> 6.6144 | L10: =I10-K10-G10 -> 55.12 | M10: =L10/I10 -> 0.83333333 | O10: =IF(J10="","",ROUNDUP(J10+0.01,0)-0.01) -> 79.99 | P10: =IF(O10="","",O10/(1+Paramètres!$B$2)) -> 66.658333 | Q10: =IF(P10="","",P10*0.1) -> 6.6658333 | R10: 1
A11: BAC-10 | B11: Bâche qualité éco | C11: 150 × 130 cm | D11: 150 | E11: 130 | F11: =D11*E11/10000 -> 1.95 | G11: =(F11*1.2*1.76+F11*1.28) -> 6.6144 | H11: =H10 -> 15 | I11: =G11*H11 -> 99.216 | J11: =IF(I11="","",I11*(1+Paramètres!$B$2)) -> 119.0592 | K11: =I11*0.1 -> 9.9216 | L11: =I11-K11-G11 -> 82.68 | M11: =L11/I11 -> 0.83333333 | O11: =IF(J11="","",ROUNDUP(J11+0.01,0)-0.01) -> 119.99 | P11: =IF(O11="","",O11/(1+Paramètres!$B$2)) -> 99.991667 | Q11: =IF(P11="","",P11*0.1) -> 9.9991667 | R11: 1
A12: BAC-11 | B12: Bâche qualité éco | C12: 200 × 130 cm | D12: 200 | E12: 130 | F12: =D12*E12/10000 -> 2.6 | G12: =(F12*1.2*1.76+F12*1.28) -> 8.8192 | H12: =H11 -> 15 | I12: =G12*H12 -> 132.288 | J12: =IF(I12="","",I12*(1+Paramètres!$B$2)) -> 158.7456 | K12: =I12*0.1 -> 13.2288 | L12: =I12-K12-G12 -> 110.24 | M12: =L12/I12 -> 0.83333333 | O12: =IF(J12="","",ROUNDUP(J12+0.01,0)-0.01) -> 158.99 | P12: =IF(O12="","",O12/(1+Paramètres!$B$2)) -> 132.49167 | Q12: =IF(P12="","",P12*0.1) -> 13.249167 | R12: 1
A13: BAC-12 | B13: Bâche qualité éco | C13: 250 × 130 cm | D13: 250 | E13: 130 | F13: =D13*E13/10000 -> 3.25 | G13: =(F13*1.2*1.76+F13*1.28) -> 11.024 | H13: =H12 -> 15 | I13: =G13*H13 -> 165.36 | J13: =IF(I13="","",I13*(1+Paramètres!$B$2)) -> 198.432 | K13: =I13*0.1 -> 16.536 | L13: =I13-K13-G13 -> 137.8 | M13: =L13/I13 -> 0.83333333 | O13: =IF(J13="","",ROUNDUP(J13+0.01,0)-0.01) -> 198.99 | P13: =IF(O13="","",O13/(1+Paramètres!$B$2)) -> 165.825 | Q13: =IF(P13="","",P13*0.1) -> 16.5825 | R13: 1
A14: BAC-13 | B14: Bâche qualité éco | C14: 300 × 130 cm | D14: 300 | E14: 130 | F14: =D14*E14/10000 -> 3.9 | G14: =(F14*1.2*1.76+F14*1.28) -> 13.2288 | H14: =H13 -> 15 | I14: =G14*H14 -> 198.432 | J14: =IF(I14="","",I14*(1+Paramètres!$B$2)) -> 238.1184 | K14: =I14*0.1 -> 19.8432 | L14: =I14-K14-G14 -> 165.36 | M14: =L14/I14 -> 0.83333333 | O14: =IF(J14="","",ROUNDUP(J14+0.01,0)-0.01) -> 238.99 | P14: =IF(O14="","",O14/(1+Paramètres!$B$2)) -> 199.15833 | Q14: =IF(P14="","",P14*0.1) -> 19.915833 | R14: 1
... A18: BAC-17 | B18: Bâche qualité éco | C18: 300 × 150 cm | D18: 300 | E18: 150 | F18: =D18*E18/10000 -> 4.5 | G18: =(F18*1.2*1.76+F18*1.28) -> 15.264 | H18: =H17 -> 15 | I18: =G18*H18 -> 228.96 | J18: =IF(I18="","",I18*(1+Paramètres!$B$2)) -> 274.752 | K18: =I18*0.1 -> 22.896 | L18: =I18-K18-G18 -> 190.8 | M18: =L18/I18 -> 0.83333333 | O18: =IF(J18="","",ROUNDUP(J18+0.01,0)-0.01) -> 274.99 | P18: =IF(O18="","",O18/(1+Paramètres!$B$2)) -> 229.15833 | Q18: =IF(P18="","",P18*0.1) -> 22.915833 | R18: 1
A19: BAC-18 | B19: Bâche qualité standard | C19: 100 × 50 cm | D19: 100 | E19: 50 | F19: =D19*E19/10000 -> 0.5 | G19: =(F19*1.2*2.4+F19*1.28) -> 2.08 | H19: =H18 -> 15 | I19: =G19*H19 -> 31.2 | J19: =IF(I19="","",I19*(1+Paramètres!$B$2)) -> 37.44 | K19: =I19*0.1 -> 3.12 | L19: =I19-K19-G19 -> 26 | M19: =L19/I19 -> 0.83333333 | O19: =IF(J19="","",ROUNDUP(J19+0.01,0)-0.01) -> 37.99 | P19: =IF(O19="","",O19/(1+Paramètres!$B$2)) -> 31.658333 | Q19: =IF(P19="","",P19*0.1) -> 3.1658333 | R19: 1
A20: BAC-19 | B20: Bâche qualité standard | C20: 150 × 50 cm | D20: 150 | E20: 50 | F20: =D20*E20/10000 -> 0.75 | G20: =(F20*1.2*2.4+F20*1.28) -> 3.12 | H20: =H19 -> 15 | I20: =G20*H20 -> 46.8 | J20: =IF(I20="","",I20*(1+Paramètres!$B$2)) -> 56.16 | K20: =I20*0.1 -> 4.68 | L20: =I20-K20-G20 -> 39 | M20: =L20/I20 -> 0.83333333 | O20: =IF(J20="","",ROUNDUP(J20+0.01,0)-0.01) -> 56.99 | P20: =IF(O20="","",O20/(1+Paramètres!$B$2)) -> 47.491667 | Q20: =IF(P20="","",P20*0.1) -> 4.7491667 | R20: 1
A21: BAC-20 | B21: Bâche qualité standard | C21: 200 × 50 cm | D21: 200 | E21: 50 | F21: =D21*E21/10000 -> 1 | G21: =(F21*1.2*2.4+F21*1.28) -> 4.16 | H21: =H20 -> 15 | I21: =G21*H21 -> 62.4 | J21: =IF(I21="","",I21*(1+Paramètres!$B$2)) -> 74.88 | K21: =I21*0.1 -> 6.24 | L21: =I21-K21-G21 -> 52 | M21: =L21/I21 -> 0.83333333 | O21: =IF(J21="","",ROUNDUP(J21+0.01,0)-0.01) -> 74.99 | P21: =IF(O21="","",O21/(1+Paramètres!$B$2)) -> 62.491667 | Q21: =IF(P21="","",P21*0.1) -> 6.2491667 | R21: 1
A22: BAC-21 | B22: Bâche qualité standard | C22: 100 × 100 cm | D22: 100 | E22: 100 | F22: =D22*E22/10000 -> 1 | G22: =(F22*1.2*2.4+F22*1.28) -> 4.16 | H22: =H21 -> 15 | I22: =G22*H22 -> 62.4 | J22: =IF(I22="","",I22*(1+Paramètres!$B$2)) -> 74.88 | K22: =I22*0.1 -> 6.24 | L22: =I22-K22-G22 -> 52 | M22: =L22/I22 -> 0.83333333 | O22: =IF(J22="","",ROUNDUP(J22+0.01,0)-0.01) -> 74.99 | P22: =IF(O22="","",O22/(1+Paramètres!$B$2)) -> 62.491667 | Q22: =IF(P22="","",P22*0.1) -> 6.2491667 | R22: 1
A23: BAC-22 | B23: Bâche qualité standard | C23: 150 × 100 cm | D23: 150 | E23: 100 | F23: =D23*E23/10000 -> 1.5 | G23: =(F23*1.2*2.4+F23*1.28) -> 6.24 | H23: =H22 -> 15 | I23: =G23*H23 -> 93.6 | J23: =IF(I23="","",I23*(1+Paramètres!$B$2)) -> 112.32 | K23: =I23*0.1 -> 9.36 | L23: =I23-K23-G23 -> 78 | M23: =L23/I23 -> 0.83333333 | O23: =IF(J23="","",ROUNDUP(J23+0.01,0)-0.01) -> 112.99 | P23: =IF(O23="","",O23/(1+Paramètres!$B$2)) -> 94.158333 | Q23: =IF(P23="","",P23*0.1) -> 9.4158333 | R23: 1
A24: BAC-23 | B24: Bâche qualité standard | C24: 200 × 100 cm | D24: 200 | E24: 100 | F24: =D24*E24/10000 -> 2 | G24: =(F24*1.2*2.4+F24*1.28) -> 8.32 | H24: =H23 -> 15 | I24: =G24*H24 -> 124.8 | J24: =IF(I24="","",I24*(1+Paramètres!$B$2)) -> 149.76 | K24: =I24*0.1 -> 12.48 | L24: =I24-K24-G24 -> 104 | M24: =L24/I24 -> 0.83333333 | O24: =IF(J24="","",ROUNDUP(J24+0.01,0)-0.01) -> 149.99 | P24: =IF(O24="","",O24/(1+Paramètres!$B$2)) -> 124.99167 | Q24: =IF(P24="","",P24*0.1) -> 12.499167 | R24: 1
A25: BAC-24 | B25: Bâche qualité standard | C25: 250 × 100 cm | D25: 250 | E25: 100 | F25: =D25*E25/10000 -> 2.5 | G25: =(F25*1.2*2.4+F25*1.28) -> 10.4 | H25: =H24 -> 15 | I25: =G25*H25 -> 156 | J25: =IF(I25="","",I25*(1+Paramètres!$B$2)) -> 187.2 | K25: =I25*0.1 -> 15.6 | L25: =I25-K25-G25 -> 130 | M25: =L25/I25 -> 0.83333333 | O25: =IF(J25="","",ROUNDUP(J25+0.01,0)-0.01) -> 187.99 | P25: =IF(O25="","",O25/(1+Paramètres!$B$2)) -> 156.65833 | Q25: =IF(P25="","",P25*0.1) -> 15.665833 | R25: 1
A26: BAC-25 | B26: Bâche qualité standard | C26: 300 × 100 cm | D26: 300 | E26: 100 | F26: =D26*E26/10000 -> 3 | G26: =(F26*1.2*2.4+F26*1.28) -> 12.48 | H26: =H25 -> 15 | I26: =G26*H26 -> 187.2 | J26: =IF(I26="","",I26*(1+Paramètres!$B$2)) -> 224.64 | K26: =I26*0.1 -> 18.72 | L26: =I26-K26-G26 -> 156 | M26: =L26/I26 -> 0.83333333 | O26: =IF(J26="","",ROUNDUP(J26+0.01,0)-0.01) -> 224.99 | P26: =IF(O26="","",O26/(1+Paramètres!$B$2)) -> 187.49167 | Q26: =IF(P26="","",P26*0.1) -> 18.749167 | R26: 1
A27: BAC-26 | B27: Bâche qualité standard | C27: 100 × 130 cm | D27: 100 | E27: 130 | F27: =D27*E27/10000 -> 1.3 | G27: =(F27*1.2*2.4+F27*1.28) -> 5.408 | H27: =H26 -> 15 | I27: =G27*H27 -> 81.12 | J27: =IF(I27="","",I27*(1+Paramètres!$B$2)) -> 97.344 | K27: =I27*0.1 -> 8.112 | L27: =I27-K27-G27 -> 67.6 | M27: =L27/I27 -> 0.83333333 | O27: =IF(J27="","",ROUNDUP(J27+0.01,0)-0.01) -> 97.99 | P27: =IF(O27="","",O27/(1+Paramètres!$B$2)) -> 81.658333 | Q27: =IF(P27="","",P27*0.1) -> 8.1658333 | R27: 1
A28: BAC-27 | B28: Bâche qualité standard | C28: 150 × 130 cm | D28: 150 | E28: 130 | F28: =D28*E28/10000 -> 1.95 | G28: =(F28*1.2*2.4+F28*1.28) -> 8.112 | H28: =H27 -> 15 | I28: =G28*H28 -> 121.68 | J28: =IF(I28="","",I28*(1+Paramètres!$B$2)) -> 146.016 | K28: =I28*0.1 -> 12.168 | L28: =I28-K28-G28 -> 101.4 | M28: =L28/I28 -> 0.83333333 | O28: =IF(J28="","",ROUNDUP(J28+0.01,0)-0.01) -> 146.99 | P28: =IF(O28="","",O28/(1+Paramètres!$B$2)) -> 122.49167 | Q28: =IF(P28="","",P28*0.1) -> 12.249167 | R28: 1
A29: BAC-28 | B29: Bâche qualité standard | C29: 200 × 130 cm | D29: 200 | E29: 130 | F29: =D29*E29/10000 -> 2.6 | G29: =(F29*1.2*2.4+F29*1.28) -> 10.816 | H29: =H28 -> 15 | I29: =G29*H29 -> 162.24 | J29: =IF(I29="","",I29*(1+Paramètres!$B$2)) -> 194.688 | K29: =I29*0.1 -> 16.224 | L29: =I29-K29-G29 -> 135.2 | M29: =L29/I29 -> 0.83333333 | O29: =IF(J29="","",ROUNDUP(J29+0.01,0)-0.01) -> 194.99 | P29: =IF(O29="","",O29/(1+Paramètres!$B$2)) -> 162.49167 | Q29: =IF(P29="","",P29*0.1) -> 16.249167 | R29: 1
A30: BAC-29 | B30: Bâche qualité standard | C30: 250 × 130 cm | D30: 250 | E30: 130 | F30: =D30*E30/10000 -> 3.25 | G30: =(F30*1.2*2.4+F30*1.28) -> 13.52 | H30: =H29 -> 15 | I30: =G30*H30 -> 202.8 | J30: =IF(I30="","",I30*(1+Paramètres!$B$2)) -> 243.36 | K30: =I30*0.1 -> 20.28 | L30: =I30-K30-G30 -> 169 | M30: =L30/I30 -> 0.83333333 | O30: =IF(J30="","",ROUNDUP(J30+0.01,0)-0.01) -> 243.99 | P30: =IF(O30="","",O30/(1+Paramètres!$B$2)) -> 203.325 | Q30: =IF(P30="","",P30*0.1) -> 20.3325 | R30: 1
... A35: BAC-34 | B35: Bâche qualité standard | C35: 300 × 150 cm | D35: 300 | E35: 150 | F35: =D35*E35/10000 -> 4.5 | G35: =(F35*1.2*2.4+F35*1.28) -> 18.72 | H35: =H34 -> 15 | I35: =G35*H35 -> 280.8 | J35: =IF(I35="","",I35*(1+Paramètres!$B$2)) -> 336.96 | K35: =I35*0.1 -> 28.08 | L35: =I35-K35-G35 -> 234 | M35: =L35/I35 -> 0.83333333 | O35: =IF(J35="","",ROUNDUP(J35+0.01,0)-0.01) -> 336.99 | P35: =IF(O35="","",O35/(1+Paramètres!$B$2)) -> 280.825 | Q35: =IF(P35="","",P35*0.1) -> 28.0825 | R35: 1
A36: BAC-35 | B36: Bâche qualité supérieure | C36: 100 × 50 cm | D36: 100 | E36: 50 | F36: =D36*E36/10000 -> 0.5 | G36: =(F36*1.2*4.24+F36*1.28) -> 3.184 | H36: =H35 -> 15 | I36: =G36*H36 -> 47.76 | J36: =IF(I36="","",I36*(1+Paramètres!$B$2)) -> 57.312 | K36: =I36*0.1 -> 4.776 | L36: =I36-K36-G36 -> 39.8 | M36: =L36/I36 -> 0.83333333 | O36: =IF(J36="","",ROUNDUP(J36+0.01,0)-0.01) -> 57.99 | P36: =IF(O36="","",O36/(1+Paramètres!$B$2)) -> 48.325 | Q36: =IF(P36="","",P36*0.1) -> 4.8325 | R36: 1
A37: BAC-36 | B37: Bâche qualité supérieure | C37: 150 × 50 cm | D37: 150 | E37: 50 | F37: =D37*E37/10000 -> 0.75 | G37: =(F37*1.2*4.24+F37*1.28) -> 4.776 | H37: =H36 -> 15 | I37: =G37*H37 -> 71.64 | J37: =IF(I37="","",I37*(1+Paramètres!$B$2)) -> 85.968 | K37: =I37*0.1 -> 7.164 | L37: =I37-K37-G37 -> 59.7 | M37: =L37/I37 -> 0.83333333 | O37: =IF(J37="","",ROUNDUP(J37+0.01,0)-0.01) -> 85.99 | P37: =IF(O37="","",O37/(1+Paramètres!$B$2)) -> 71.658333 | Q37: =IF(P37="","",P37*0.1) -> 7.1658333 | R37: 1
A38: BAC-37 | B38: Bâche qualité supérieure | C38: 200 × 50 cm | D38: 200 | E38: 50 | F38: =D38*E38/10000 -> 1 | G38: =(F38*1.2*4.24+F38*1.28) -> 6.368 | H38: =H37 -> 15 | I38: =G38*H38 -> 95.52 | J38: =IF(I38="","",I38*(1+Paramètres!$B$2)) -> 114.624 | K38: =I38*0.1 -> 9.552 | L38: =I38-K38-G38 -> 79.6 | M38: =L38/I38 -> 0.83333333 | O38: =IF(J38="","",ROUNDUP(J38+0.01,0)-0.01) -> 114.99 | P38: =IF(O38="","",O38/(1+Paramètres!$B$2)) -> 95.825 | Q38: =IF(P38="","",P38*0.1) -> 9.5825 | R38: 1
A39: BAC-38 | B39: Bâche qualité supérieure | C39: 100 × 100 cm | D39: 100 | E39: 100 | F39: =D39*E39/10000 -> 1 | G39: =(F39*1.2*4.24+F39*1.28) -> 6.368 | H39: =H38 -> 15 | I39: =G39*H39 -> 95.52 | J39: =IF(I39="","",I39*(1+Paramètres!$B$2)) -> 114.624 | K39: =I39*0.1 -> 9.552 | L39: =I39-K39-G39 -> 79.6 | M39: =L39/I39 -> 0.83333333 | O39: =IF(J39="","",ROUNDUP(J39+0.01,0)-0.01) -> 114.99 | P39: =IF(O39="","",O39/(1+Paramètres!$B$2)) -> 95.825 | Q39: =IF(P39="","",P39*0.1) -> 9.5825 | R39: 1
A40: BAC-39 | B40: Bâche qualité supérieure | C40: 150 × 100 cm | D40: 150 | E40: 100 | F40: =D40*E40/10000 -> 1.5 | G40: =(F40*1.2*4.24+F40*1.28) -> 9.552 | H40: =H39 -> 15 | I40: =G40*H40 -> 143.28 | J40: =IF(I40="","",I40*(1+Paramètres!$B$2)) -> 171.936 | K40: =I40*0.1 -> 14.328 | L40: =I40-K40-G40 -> 119.4 | M40: =L40/I40 -> 0.83333333 | O40: =IF(J40="","",ROUNDUP(J40+0.01,0)-0.01) -> 171.99 | P40: =IF(O40="","",O40/(1+Paramètres!$B$2)) -> 143.325 | Q40: =IF(P40="","",P40*0.1) -> 14.3325 | R40: 1
A41: BAC-40 | B41: Bâche qualité supérieure | C41: 200 × 100 cm | D41: 200 | E41: 100 | F41: =D41*E41/10000 -> 2 | G41: =(F41*1.2*4.24+F41*1.28) -> 12.736 | H41: =H40 -> 15 | I41: =G41*H41 -> 191.04 | J41: =IF(I41="","",I41*(1+Paramètres!$B$2)) -> 229.248 | K41: =I41*0.1 -> 19.104 | L41: =I41-K41-G41 -> 159.2 | M41: =L41/I41 -> 0.83333333 | O41: =IF(J41="","",ROUNDUP(J41+0.01,0)-0.01) -> 229.99 | P41: =IF(O41="","",O41/(1+Paramètres!$B$2)) -> 191.65833 | Q41: =IF(P41="","",P41*0.1) -> 19.165833 | R41: 1
A42: BAC-41 | B42: Bâche qualité supérieure | C42: 250 × 100 cm | D42: 250 | E42: 100 | F42: =D42*E42/10000 -> 2.5 | G42: =(F42*1.2*4.24+F42*1.28) -> 15.92 | H42: =H41 -> 15 | I42: =G42*H42 -> 238.8 | J42: =IF(I42="","",I42*(1+Paramètres!$B$2)) -> 286.56 | K42: =I42*0.1 -> 23.88 | L42: =I42-K42-G42 -> 199 | M42: =L42/I42 -> 0.83333333 | O42: =IF(J42="","",ROUNDUP(J42+0.01,0)-0.01) -> 286.99 | P42: =IF(O42="","",O42/(1+Paramètres!$B$2)) -> 239.15833 | Q42: =IF(P42="","",P42*0.1) -> 23.915833 | R42: 1
A43: BAC-42 | B43: Bâche qualité supérieure | C43: 300 × 100 cm | D43: 300 | E43: 100 | F43: =D43*E43/10000 -> 3 | G43: =(F43*1.2*4.24+F43*1.28) -> 19.104 | H43: =H42 -> 15 | I43: =G43*H43 -> 286.56 | J43: =IF(I43="","",I43*(1+Paramètres!$B$2)) -> 343.872 | K43: =I43*0.1 -> 28.656 | L43: =I43-K43-G43 -> 238.8 | M43: =L43/I43 -> 0.83333333 | O43: =IF(J43="","",ROUNDUP(J43+0.01,0)-0.01) -> 343.99 | P43: =IF(O43="","",O43/(1+Paramètres!$B$2)) -> 286.65833 | Q43: =IF(P43="","",P43*0.1) -> 28.665833 | R43: 1
A44: BAC-43 | B44: Bâche qualité supérieure | C44: 100 × 130 cm | D44: 100 | E44: 130 | F44: =D44*E44/10000 -> 1.3 | G44: =(F44*1.2*4.24+F44*1.28) -> 8.2784 | H44: =H43 -> 15 | I44: =G44*H44 -> 124.176 | J44: =IF(I44="","",I44*(1+Paramètres!$B$2)) -> 149.0112 | K44: =I44*0.1 -> 12.4176 | L44: =I44-K44-G44 -> 103.48 | M44: =L44/I44 -> 0.83333333 | O44: =IF(J44="","",ROUNDUP(J44+0.01,0)-0.01) -> 149.99 | P44: =IF(O44="","",O44/(1+Paramètres!$B$2)) -> 124.99167 | Q44: =IF(P44="","",P44*0.1) -> 12.499167 | R44: 1
A45: BAC-44 | B45: Bâche qualité supérieure | C45: 150 × 130 cm | D45: 150 | E45: 130 | F45: =D45*E45/10000 -> 1.95 | G45: =(F45*1.2*4.24+F45*1.28) -> 12.4176 | H45: =H44 -> 15 | I45: =G45*H45 -> 186.264 | J45: =IF(I45="","",I45*(1+Paramètres!$B$2)) -> 223.5168 | K45: =I45*0.1 -> 18.6264 | L45: =I45-K45-G45 -> 155.22 | M45: =L45/I45 -> 0.83333333 | O45: =IF(J45="","",ROUNDUP(J45+0.01,0)-0.01) -> 223.99 | P45: =IF(O45="","",O45/(1+Paramètres!$B$2)) -> 186.65833 | Q45: =IF(P45="","",P45*0.1) -> 18.665833 | R45: 1
A46: BAC-45 | B46: Bâche qualité supérieure | C46: 200 × 130 cm | D46: 200 | E46: 130 | F46: =D46*E46/10000 -> 2.6 | G46: =(F46*1.2*4.24+F46*1.28) -> 16.5568 | H46: =H45 -> 15 | I46: =G46*H46 -> 248.352 | J46: =IF(I46="","",I46*(1+Paramètres!$B$2)) -> 298.0224 | K46: =I46*0.1 -> 24.8352 | L46: =I46-K46-G46 -> 206.96 | M46: =L46/I46 -> 0.83333333 | O46: =IF(J46="","",ROUNDUP(J46+0.01,0)-0.01) -> 298.99 | P46: =IF(O46="","",O46/(1+Paramètres!$B$2)) -> 249.15833 | Q46: =IF(P46="","",P46*0.1) -> 24.915833 | R46: 1
A47: BAC-46 | B47: Bâche qualité supérieure | C47: 250 × 130 cm | D47: 250 | E47: 130 | F47: =D47*E47/10000 -> 3.25 | G47: =(F47*1.2*4.24+F47*1.28) -> 20.696 | H47: =H46 -> 15 | I47: =G47*H47 -> 310.44 | J47: =IF(I47="","",I47*(1+Paramètres!$B$2)) -> 372.528 | K47: =I47*0.1 -> 31.044 | L47: =I47-K47-G47 -> 258.7 | M47: =L47/I47 -> 0.83333333 | O47: =IF(J47="","",ROUNDUP(J47+0.01,0)-0.01) -> 372.99 | P47: =IF(O47="","",O47/(1+Paramètres!$B$2)) -> 310.825 | Q47: =IF(P47="","",P47*0.1) -> 31.0825 | R47: 1
...

Sheet Paramètres
A1: Paramètre | B1: Valeur
A2: Taux de TVA | B2: 0.2 | C2: Hypothèse : TVA française 20 % (ventes UE via OSS à traiter à part)

Sheet Finitions
A1: Support | B1: Reference | D1: Finition | E1: Type | F1: Supplément HT (€)
A2: Bâche | D2: Œillets | E2: Oeuillets aluminium | F2: 4.5
A3: Bâche | D3: Tendeur crochet | E3: Tendeur crochet | F3: 7.5
A4: Tableau alu (Dibond) | B4: frame.board_châssis.15 | C4: 20 x 20 cm | D4: Système d'accroche au dos | E4: Barres aluminium | F4: 10
A5: Tableau alu (Dibond) | B5: frame.board_châssis.16 | C5: 20 x 30 cm | D5: Système d'accroche au dos | E5: Barres aluminium | F5: 10
A6: Tableau alu (Dibond) | B6: frame.board_châssis.17 | C6: 30 × 40 cm | D6: Système d'accroche au dos | E6: Barres aluminium | F6: 10
A7: Tableau alu (Dibond) | B7: frame.board_châssis.18 | C7: 40 × 60 cm | D7: Système d'accroche au dos | E7: Barres aluminium | F7: 15
A8: Tableau alu (Dibond) | B8: frame.board_châssis.19 | C8: 60 × 90 cm | D8: Système d'accroche au dos | E8: Barres aluminium | F8: 15
A9: Tableau alu (Dibond) | B9: frame.board_châssis.20 | C9: 80 × 120 cm | D9: Système d'accroche au dos | E9: Barres aluminium | F9: 15
A10: Tableau alu (Dibond) | B10: frame.board_châssis.21 | C10: 100 × 150 cm | D10: Système d'accroche au dos | E10: Barres aluminium | F10: 15
A11: Tableau alu (Dibond) | B11: ALU-01frame.board_L25 - BLANC | C11: 20 x 20 cm | D11: Cadre aluminium blanc | F11: 15
A12: Tableau alu (Dibond) | B12: ALU-01frame.board_L25 - BLANC | C12: 20 x 30 cm | D12: Cadre aluminium blanc | F12: 15
A13: Tableau alu (Dibond) | B13: ALU-01frame.board_L25 - BLANC | C13: 30 × 40 cm | D13: Cadre aluminium blanc | F13: 15
A14: Tableau alu (Dibond) | B14: ALU-01frame.board_L25 - BLANC | C14: 40 × 60 cm | D14: Cadre aluminium blanc | F14: 15
A15: Tableau alu (Dibond) | B15: ALU-01frame.board_L25 - BLANC | C15: 60 × 90 cm | D15: Cadre aluminium blanc | F15: 15
A16: Tableau alu (Dibond) | B16: ALU-01frame.board_L25 - BLANC | C16: 80 × 120 cm | D16: Cadre aluminium blanc | F16: 15
A17: Tableau alu (Dibond) | B17: ALU-01frame.board_L25 - BLANC | C17: 100 × 150 cm | D17: Cadre aluminium blanc | F17: 15
A18: Tableau alu (Dibond) | B18: ALU-01frame.board_L25 - NOIR | C18: 20 x 20 cm | D18: Cadre aluminium noir | F18: 15
A19: Tableau alu (Dibond) | B19: ALU-01frame.board_L25 - NOIR | C19: 20 x 30 cm | D19: Cadre aluminium noir | F19: 15
A20: Tableau alu (Dibond) | B20: ALU-01frame.board_L25 - NOIR | C20: 30 × 40 cm | D20: Cadre aluminium noir | F20: 15
A21: Tableau alu (Dibond) | B21: ALU-01frame.board_L25 - NOIR | C21: 40 × 60 cm | D21: Cadre aluminium noir | F21: 15
A22: Tableau alu (Dibond) | B22: ALU-01frame.board_L25 - NOIR | C22: 60 × 90 cm | D22: Cadre aluminium noir | F22: 15
... A24: Tableau alu (Dibond) | B24: ALU-01frame.board_L25 - NOIR | C24: 100 × 150 cm | D24: Cadre aluminium noir | F24: 15
